telegram.ext.updater - ERROR - Error while getting Updates: Timed out
telegram.ext.updater - ERROR - Error while getting Updates: Timed out
telegram.ext.updater - ERROR - Error while getting Updates: Timed out
telegram.ext.updater - ERROR - Error while getting Updates: Timed out
telegram.ext.updater - ERROR - Error while getting Updates: Timed out
telegram.ext.updater - ERROR - Error while getting Updates: Timed out
telegram.ext.updater - WARNING - Exiting immediately!
telegram.ext.updater - WARNING - Exiting immediately!
telegram.ext.updater - WARNING - Exiting immediately!
telegram.ext.updater - WARNING - Exiting immediately!
telegram.ext.updater - WARNING - Exiting immediately!
telegram.ext.updater - WARNING - Exiting immediately!
telegram.ext.updater - WARNING - Exiting immediately!
telegram.ext.updater - ERROR - Error while getting Updates: Timed out
telegram.ext.updater - ERROR - Error while getting Updates: Timed out
telegram.ext.updater - WARNING - Exiting immediately!
telegram.ext.updater - WARNING - Exiting immediately!
telegram.ext.updater - ERROR - Error while getting Updates: Timed out
telegram.ext.updater - WARNING - Exiting immediately!
telegram.ext.updater - ERROR - Error while getting Updates: Timed out
telegram.ext.updater - WARNING - Exiting immediately!
telegram.ext.updater - WARNING - Exiting immediately!
telegram.ext.updater - WARNING - Exiting immediately!
telegram.ext.updater - WARNING - Exiting immediately!
telegram.ext.dispatcher - WARNING - A TelegramError was raised while processing the Update
telegram.ext.dispatcher - ERROR - No error handlers are registered, logging exception...
Traceback (most recent call last):
  File "C:\Python34\lib\site-packages\telegram\ext\dispatcher.py", line 279, in process_update
    handler.handle_update(update, self)
  File "C:\Python34\lib\site-packages\telegram\ext\commandhandler.py", line 171, in handle_update
    return self.callback(dispatcher.bot, update, **optional_args)
  File "bot.py", line 26, in define_constellation
    update.message.reply_text(text)
  File "C:\Python34\lib\site-packages\telegram\message.py", line 427, in reply_text
    return self.bot.send_message(self.chat_id, *args, **kwargs)
  File "C:\Python34\lib\site-packages\telegram\bot.py", line 60, in decorator
    result = func(self, *args, **kwargs)
  File "C:\Python34\lib\site-packages\telegram\bot.py", line 85, in decorator
    result = self._request.post(url, data, timeout=kwargs.get('timeout'))
  File "C:\Python34\lib\site-packages\telegram\utils\request.py", line 272, in post
    **urlopen_kwargs)
  File "C:\Python34\lib\site-packages\telegram\utils\request.py", line 210, in _request_wrapper
    raise BadRequest(message)
telegram.error.BadRequest: Message text is empty
telegram.ext.updater - WARNING - Exiting immediately!
telegram.ext.updater - ERROR - Error while getting Updates: Timed out
telegram.ext.updater - ERROR - Error while getting Updates: Timed out
telegram.ext.updater - ERROR - Error while getting Updates: Timed out
telegram.ext.updater - ERROR - Error while getting Updates: Timed out
telegram.ext.updater - ERROR - Error while getting Updates: Timed out
telegram.ext.updater - WARNING - Exiting immediately!
telegram.vendor.ptb_urllib3.urllib3.connectionpool - WARNING - Retrying (Retry(total=2, connect=None, read=None, redirect=None)) after connection broken by 'ConnectTimeoutError(<telegram.vendor.ptb_urllib3.urllib3.connection.VerifiedHTTPSConnection object at 0x000000000347CC18>, 'Connection to api.telegram.org timed out. (connect timeout=5.0)')': /bot528362717:AAGzWK5d0NEkICKK06izaiOoN80jNsqJYrg/setWebhook
telegram.ext.dispatcher - WARNING - A TelegramError was raised while processing the Update
telegram.ext.dispatcher - ERROR - No error handlers are registered, logging exception...
Traceback (most recent call last):
  File "C:\Python34\lib\site-packages\telegram\ext\dispatcher.py", line 279, in process_update
    handler.handle_update(update, self)
  File "C:\Python34\lib\site-packages\telegram\ext\commandhandler.py", line 171, in handle_update
    return self.callback(dispatcher.bot, update, **optional_args)
  File "bot.py", line 26, in define_constellation
    update.message.reply_text(text)
  File "C:\Python34\lib\site-packages\telegram\message.py", line 427, in reply_text
    return self.bot.send_message(self.chat_id, *args, **kwargs)
  File "C:\Python34\lib\site-packages\telegram\bot.py", line 60, in decorator
    result = func(self, *args, **kwargs)
  File "C:\Python34\lib\site-packages\telegram\bot.py", line 85, in decorator
    result = self._request.post(url, data, timeout=kwargs.get('timeout'))
  File "C:\Python34\lib\site-packages\telegram\utils\request.py", line 272, in post
    **urlopen_kwargs)
  File "C:\Python34\lib\site-packages\telegram\utils\request.py", line 210, in _request_wrapper
    raise BadRequest(message)
telegram.error.BadRequest: Message text is empty
telegram.ext.updater - WARNING - Exiting immediately!
telegram.ext.updater - WARNING - Exiting immediately!
telegram.ext.updater - ERROR - Error while getting Updates: Timed out
telegram.ext.updater - ERROR - Error while getting Updates: Timed out
telegram.ext.updater - ERROR - Error while getting Updates: Timed out
telegram.ext.updater - ERROR - Error while getting Updates: Timed out
telegram.ext.updater - WARNING - Exiting immediately!
telegram.ext.updater - WARNING - Exiting immediately!
telegram.ext.updater - WARNING - Exiting immediately!
telegram.ext.updater - WARNING - Exiting immediately!
telegram.ext.updater - WARNING - Exiting immediately!
telegram.ext.updater - WARNING - Exiting immediately!
2018-02-24 00:24:19,588: telegram.ext.dispatcher - ERROR - An uncaught error was raised while processing the update
Traceback (most recent call last):
  File "C:\Python34\lib\site-packages\telegram\ext\dispatcher.py", line 279, in process_update
    handler.handle_update(update, self)
  File "C:\Python34\lib\site-packages\telegram\ext\commandhandler.py", line 171, in handle_update
    return self.callback(dispatcher.bot, update, **optional_args)
  File "bot_2.py", line 51, in get_constellation
    planet.message.reply_text(constellation)
UnboundLocalError: local variable 'constellation' referenced before assignment
2018-02-24 00:25:32,829: telegram.ext.updater - WARNING - Exiting immediately!
2018-02-24 00:26:35,323: telegram.ext.updater - WARNING - Exiting immediately!
2018-02-24 00:26:39,839: telegram.ext.dispatcher - ERROR - An uncaught error was raised while processing the update
Traceback (most recent call last):
  File "C:\Python34\lib\site-packages\telegram\ext\dispatcher.py", line 279, in process_update
    handler.handle_update(update, self)
  File "C:\Python34\lib\site-packages\telegram\ext\commandhandler.py", line 171, in handle_update
    return self.callback(dispatcher.bot, update, **optional_args)
  File "bot_2.py", line 41, in get_constellation
    update.message.reply_text(text)
NameError: name 'update' is not defined
2018-02-24 00:28:09,542: telegram.ext.updater - ERROR - Error while getting Updates: Timed out
2018-02-24 00:30:42,525: telegram.ext.updater - WARNING - Exiting immediately!
2018-02-24 00:30:49,619: telegram.ext.updater - WARNING - Exiting immediately!
telegram.ext.updater - WARNING - Exiting immediately!
telegram.ext.updater - WARNING - Exiting immediately!
telegram.ext.updater - WARNING - Exiting immediately!
telegram.ext.updater - ERROR - Error while getting Updates: Timed out
telegram.ext.updater - WARNING - Exiting immediately!
telegram.ext.dispatcher - WARNING - A TelegramError was raised while processing the Update
telegram.ext.dispatcher - ERROR - No error handlers are registered, logging exception...
Traceback (most recent call last):
  File "C:\Python34\lib\site-packages\telegram\ext\dispatcher.py", line 279, in process_update
    handler.handle_update(update, self)
  File "C:\Python34\lib\site-packages\telegram\ext\commandhandler.py", line 171, in handle_update
    return self.callback(dispatcher.bot, update, **optional_args)
  File "bot.py", line 28, in define_constellation
    update.message.reply_text(text)
  File "C:\Python34\lib\site-packages\telegram\message.py", line 427, in reply_text
    return self.bot.send_message(self.chat_id, *args, **kwargs)
  File "C:\Python34\lib\site-packages\telegram\bot.py", line 60, in decorator
    result = func(self, *args, **kwargs)
  File "C:\Python34\lib\site-packages\telegram\bot.py", line 85, in decorator
    result = self._request.post(url, data, timeout=kwargs.get('timeout'))
  File "C:\Python34\lib\site-packages\telegram\utils\request.py", line 272, in post
    **urlopen_kwargs)
  File "C:\Python34\lib\site-packages\telegram\utils\request.py", line 210, in _request_wrapper
    raise BadRequest(message)
telegram.error.BadRequest: Message text is empty
telegram.ext.updater - WARNING - Exiting immediately!
telegram.ext.updater - ERROR - Error while getting Updates: Timed out
telegram.ext.updater - WARNING - Exiting immediately!
telegram.ext.updater - WARNING - Exiting immediately!
telegram.ext.updater - WARNING - Exiting immediately!
telegram.ext.updater - WARNING - Exiting immediately!
telegram.ext.updater - ERROR - Error while getting Updates: Timed out
telegram.ext.updater - ERROR - Error while getting Updates: Timed out
telegram.ext.updater - ERROR - Error while getting Updates: Timed out
telegram.ext.updater - ERROR - Error while getting Updates: Timed out
telegram.ext.updater - ERROR - Error while getting Updates: Timed out
telegram.ext.updater - ERROR - Error while getting Updates: Timed out
telegram.ext.updater - ERROR - Error while getting Updates: Timed out
telegram.ext.updater - ERROR - Error while getting Updates: Timed out
telegram.ext.updater - ERROR - Error while getting Updates: Timed out
telegram.ext.updater - ERROR - Error while getting Updates: Timed out
telegram.ext.updater - ERROR - Error while getting Updates: Timed out
telegram.ext.updater - ERROR - Error while getting Updates: Timed out
telegram.ext.updater - ERROR - Error while getting Updates: Timed out
telegram.ext.updater - ERROR - Error while getting Updates: Timed out
telegram.ext.updater - ERROR - Error while getting Updates: Timed out
telegram.ext.updater - ERROR - Error while getting Updates: Timed out
telegram.ext.updater - ERROR - Error while getting Updates: Timed out
telegram.ext.updater - ERROR - Error while getting Updates: Timed out
telegram.ext.updater - ERROR - Error while getting Updates: Timed out
telegram.ext.updater - ERROR - Error while getting Updates: Timed out
telegram.ext.updater - ERROR - Error while getting Updates: Timed out
telegram.ext.updater - ERROR - Error while getting Updates: Timed out
telegram.ext.updater - ERROR - Error while getting Updates: Timed out
telegram.ext.updater - ERROR - Error while getting Updates: Timed out
telegram.ext.updater - ERROR - Error while getting Updates: Timed out
telegram.ext.updater - ERROR - Error while getting Updates: Timed out
telegram.ext.updater - ERROR - Error while getting Updates: Timed out
telegram.ext.updater - ERROR - Error while getting Updates: Timed out
telegram.ext.updater - ERROR - Error while getting Updates: Timed out
telegram.ext.updater - ERROR - Error while getting Updates: Timed out
telegram.ext.updater - ERROR - Error while getting Updates: Timed out
telegram.ext.updater - ERROR - Error while getting Updates: Timed out
telegram.ext.updater - ERROR - Error while getting Updates: Timed out
telegram.ext.updater - ERROR - Error while getting Updates: Timed out
telegram.ext.updater - ERROR - Error while getting Updates: Timed out
telegram.ext.updater - ERROR - Error while getting Updates: Timed out
telegram.ext.updater - ERROR - Error while getting Updates: Timed out
telegram.ext.updater - ERROR - Error while getting Updates: Timed out
telegram.ext.updater - ERROR - Error while getting Updates: Timed out
telegram.ext.updater - ERROR - Error while getting Updates: Timed out
telegram.ext.updater - ERROR - Error while getting Updates: Timed out
telegram.ext.updater - ERROR - Error while getting Updates: Timed out
telegram.ext.updater - ERROR - Error while getting Updates: Timed out
telegram.ext.updater - ERROR - Error while getting Updates: Timed out
telegram.ext.updater - ERROR - Error while getting Updates: Timed out
telegram.ext.updater - ERROR - Error while getting Updates: Timed out
telegram.ext.updater - ERROR - Error while getting Updates: Timed out
telegram.ext.updater - ERROR - Error while getting Updates: Timed out
telegram.ext.updater - ERROR - Error while getting Updates: Timed out
telegram.ext.updater - ERROR - Error while getting Updates: Timed out
telegram.ext.updater - ERROR - Error while getting Updates: Timed out
telegram.ext.updater - ERROR - Error while getting Updates: Timed out
telegram.vendor.ptb_urllib3.urllib3.connectionpool - WARNING - Retrying (Retry(total=2, connect=None, read=None, redirect=None)) after connection broken by 'ConnectTimeoutError(<telegram.vendor.ptb_urllib3.urllib3.connectionpool.HTTPSConnectionPool object at 0x00000000033FCB70>, 'Connect timed out. (connect timeout=5.0)')': /bot528362717:AAGzWK5d0NEkICKK06izaiOoN80jNsqJYrg/getUpdates
telegram.vendor.ptb_urllib3.urllib3.connectionpool - WARNING - Retrying (Retry(total=1, connect=None, read=None, redirect=None)) after connection broken by 'ConnectTimeoutError(<telegram.vendor.ptb_urllib3.urllib3.connection.VerifiedHTTPSConnection object at 0x0000000003514240>, 'Connection to api.telegram.org timed out. (connect timeout=5.0)')': /bot528362717:AAGzWK5d0NEkICKK06izaiOoN80jNsqJYrg/getUpdates
telegram.vendor.ptb_urllib3.urllib3.connectionpool - WARNING - Retrying (Retry(total=0, connect=None, read=None, redirect=None)) after connection broken by 'ConnectTimeoutError(<telegram.vendor.ptb_urllib3.urllib3.connection.VerifiedHTTPSConnection object at 0x0000000003514978>, 'Connection to api.telegram.org timed out. (connect timeout=5.0)')': /bot528362717:AAGzWK5d0NEkICKK06izaiOoN80jNsqJYrg/getUpdates
telegram.ext.updater - ERROR - Error while getting Updates: urllib3 HTTPError HTTPSConnectionPool(host='api.telegram.org', port=443): Max retries exceeded with url: /bot528362717:AAGzWK5d0NEkICKK06izaiOoN80jNsqJYrg/getUpdates (Caused by ConnectTimeoutError(<telegram.vendor.ptb_urllib3.urllib3.connection.VerifiedHTTPSConnection object at 0x0000000003514DA0>, 'Connection to api.telegram.org timed out. (connect timeout=5.0)'))
telegram.vendor.ptb_urllib3.urllib3.connectionpool - WARNING - Retrying (Retry(total=2, connect=None, read=None, redirect=None)) after connection broken by 'ConnectTimeoutError(<telegram.vendor.ptb_urllib3.urllib3.connection.VerifiedHTTPSConnection object at 0x00000000035146D8>, 'Connection to api.telegram.org timed out. (connect timeout=5.0)')': /bot528362717:AAGzWK5d0NEkICKK06izaiOoN80jNsqJYrg/getUpdates
telegram.vendor.ptb_urllib3.urllib3.connectionpool - WARNING - Retrying (Retry(total=1, connect=None, read=None, redirect=None)) after connection broken by 'ConnectTimeoutError(<telegram.vendor.ptb_urllib3.urllib3.connection.VerifiedHTTPSConnection object at 0x0000000003514160>, 'Connection to api.telegram.org timed out. (connect timeout=5.0)')': /bot528362717:AAGzWK5d0NEkICKK06izaiOoN80jNsqJYrg/getUpdates
telegram.vendor.ptb_urllib3.urllib3.connectionpool - WARNING - Retrying (Retry(total=0, connect=None, read=None, redirect=None)) after connection broken by 'ConnectTimeoutError(<telegram.vendor.ptb_urllib3.urllib3.connection.VerifiedHTTPSConnection object at 0x0000000003514080>, 'Connection to api.telegram.org timed out. (connect timeout=5.0)')': /bot528362717:AAGzWK5d0NEkICKK06izaiOoN80jNsqJYrg/getUpdates
telegram.ext.updater - ERROR - Error while getting Updates: urllib3 HTTPError HTTPSConnectionPool(host='api.telegram.org', port=443): Max retries exceeded with url: /bot528362717:AAGzWK5d0NEkICKK06izaiOoN80jNsqJYrg/getUpdates (Caused by ConnectTimeoutError(<telegram.vendor.ptb_urllib3.urllib3.connection.VerifiedHTTPSConnection object at 0x00000000035146A0>, 'Connection to api.telegram.org timed out. (connect timeout=5.0)'))
telegram.vendor.ptb_urllib3.urllib3.connectionpool - WARNING - Retrying (Retry(total=2, connect=None, read=None, redirect=None)) after connection broken by 'ConnectTimeoutError(<telegram.vendor.ptb_urllib3.urllib3.connection.VerifiedHTTPSConnection object at 0x0000000003514DD8>, 'Connection to api.telegram.org timed out. (connect timeout=5.0)')': /bot528362717:AAGzWK5d0NEkICKK06izaiOoN80jNsqJYrg/getUpdates
telegram.vendor.ptb_urllib3.urllib3.connectionpool - WARNING - Retrying (Retry(total=1, connect=None, read=None, redirect=None)) after connection broken by 'ConnectTimeoutError(<telegram.vendor.ptb_urllib3.urllib3.connection.VerifiedHTTPSConnection object at 0x0000000003514A20>, 'Connection to api.telegram.org timed out. (connect timeout=5.0)')': /bot528362717:AAGzWK5d0NEkICKK06izaiOoN80jNsqJYrg/getUpdates
telegram.vendor.ptb_urllib3.urllib3.connectionpool - WARNING - Retrying (Retry(total=0, connect=None, read=None, redirect=None)) after connection broken by 'ConnectTimeoutError(<telegram.vendor.ptb_urllib3.urllib3.connection.VerifiedHTTPSConnection object at 0x0000000003514BE0>, 'Connection to api.telegram.org timed out. (connect timeout=5.0)')': /bot528362717:AAGzWK5d0NEkICKK06izaiOoN80jNsqJYrg/getUpdates
telegram.ext.updater - ERROR - Error while getting Updates: urllib3 HTTPError HTTPSConnectionPool(host='api.telegram.org', port=443): Max retries exceeded with url: /bot528362717:AAGzWK5d0NEkICKK06izaiOoN80jNsqJYrg/getUpdates (Caused by ConnectTimeoutError(<telegram.vendor.ptb_urllib3.urllib3.connection.VerifiedHTTPSConnection object at 0x0000000003514C50>, 'Connection to api.telegram.org timed out. (connect timeout=5.0)'))
telegram.vendor.ptb_urllib3.urllib3.connectionpool - WARNING - Retrying (Retry(total=2, connect=None, read=None, redirect=None)) after connection broken by 'ConnectTimeoutError(<telegram.vendor.ptb_urllib3.urllib3.connection.VerifiedHTTPSConnection object at 0x0000000003525390>, 'Connection to api.telegram.org timed out. (connect timeout=5.0)')': /bot528362717:AAGzWK5d0NEkICKK06izaiOoN80jNsqJYrg/getUpdates
telegram.vendor.ptb_urllib3.urllib3.connectionpool - WARNING - Retrying (Retry(total=1, connect=None, read=None, redirect=None)) after connection broken by 'ConnectTimeoutError(<telegram.vendor.ptb_urllib3.urllib3.connection.VerifiedHTTPSConnection object at 0x0000000003525D68>, 'Connection to api.telegram.org timed out. (connect timeout=5.0)')': /bot528362717:AAGzWK5d0NEkICKK06izaiOoN80jNsqJYrg/getUpdates
telegram.vendor.ptb_urllib3.urllib3.connectionpool - WARNING - Retrying (Retry(total=0, connect=None, read=None, redirect=None)) after connection broken by 'ConnectTimeoutError(<telegram.vendor.ptb_urllib3.urllib3.connection.VerifiedHTTPSConnection object at 0x00000000035259E8>, 'Connection to api.telegram.org timed out. (connect timeout=5.0)')': /bot528362717:AAGzWK5d0NEkICKK06izaiOoN80jNsqJYrg/getUpdates
telegram.ext.updater - ERROR - Error while getting Updates: urllib3 HTTPError HTTPSConnectionPool(host='api.telegram.org', port=443): Max retries exceeded with url: /bot528362717:AAGzWK5d0NEkICKK06izaiOoN80jNsqJYrg/getUpdates (Caused by ConnectTimeoutError(<telegram.vendor.ptb_urllib3.urllib3.connection.VerifiedHTTPSConnection object at 0x0000000003525A90>, 'Connection to api.telegram.org timed out. (connect timeout=5.0)'))
telegram.vendor.ptb_urllib3.urllib3.connectionpool - WARNING - Retrying (Retry(total=2, connect=None, read=None, redirect=None)) after connection broken by 'ConnectTimeoutError(<telegram.vendor.ptb_urllib3.urllib3.connection.VerifiedHTTPSConnection object at 0x0000000003525978>, 'Connection to api.telegram.org timed out. (connect timeout=5.0)')': /bot528362717:AAGzWK5d0NEkICKK06izaiOoN80jNsqJYrg/getUpdates
telegram.vendor.ptb_urllib3.urllib3.connectionpool - WARNING - Retrying (Retry(total=1, connect=None, read=None, redirect=None)) after connection broken by 'ConnectTimeoutError(<telegram.vendor.ptb_urllib3.urllib3.connection.VerifiedHTTPSConnection object at 0x00000000035252E8>, 'Connection to api.telegram.org timed out. (connect timeout=5.0)')': /bot528362717:AAGzWK5d0NEkICKK06izaiOoN80jNsqJYrg/getUpdates
telegram.vendor.ptb_urllib3.urllib3.connectionpool - WARNING - Retrying (Retry(total=0, connect=None, read=None, redirect=None)) after connection broken by 'ConnectTimeoutError(<telegram.vendor.ptb_urllib3.urllib3.connection.VerifiedHTTPSConnection object at 0x00000000035258D0>, 'Connection to api.telegram.org timed out. (connect timeout=5.0)')': /bot528362717:AAGzWK5d0NEkICKK06izaiOoN80jNsqJYrg/getUpdates
telegram.ext.updater - ERROR - Error while getting Updates: urllib3 HTTPError HTTPSConnectionPool(host='api.telegram.org', port=443): Max retries exceeded with url: /bot528362717:AAGzWK5d0NEkICKK06izaiOoN80jNsqJYrg/getUpdates (Caused by ConnectTimeoutError(<telegram.vendor.ptb_urllib3.urllib3.connection.VerifiedHTTPSConnection object at 0x00000000035253C8>, 'Connection to api.telegram.org timed out. (connect timeout=5.0)'))
telegram.vendor.ptb_urllib3.urllib3.connectionpool - WARNING - Retrying (Retry(total=2, connect=None, read=None, redirect=None)) after connection broken by 'ConnectTimeoutError(<telegram.vendor.ptb_urllib3.urllib3.connection.VerifiedHTTPSConnection object at 0x000000000341FC88>, 'Connection to api.telegram.org timed out. (connect timeout=5.0)')': /bot528362717:AAGzWK5d0NEkICKK06izaiOoN80jNsqJYrg/getUpdates
telegram.vendor.ptb_urllib3.urllib3.connectionpool - WARNING - Retrying (Retry(total=1, connect=None, read=None, redirect=None)) after connection broken by 'ConnectTimeoutError(<telegram.vendor.ptb_urllib3.urllib3.connection.VerifiedHTTPSConnection object at 0x000000000341FB70>, 'Connection to api.telegram.org timed out. (connect timeout=5.0)')': /bot528362717:AAGzWK5d0NEkICKK06izaiOoN80jNsqJYrg/getUpdates
telegram.vendor.ptb_urllib3.urllib3.connectionpool - WARNING - Retrying (Retry(total=0, connect=None, read=None, redirect=None)) after connection broken by 'ConnectTimeoutError(<telegram.vendor.ptb_urllib3.urllib3.connection.VerifiedHTTPSConnection object at 0x000000000341FEB8>, 'Connection to api.telegram.org timed out. (connect timeout=5.0)')': /bot528362717:AAGzWK5d0NEkICKK06izaiOoN80jNsqJYrg/getUpdates
telegram.ext.updater - ERROR - Error while getting Updates: urllib3 HTTPError HTTPSConnectionPool(host='api.telegram.org', port=443): Max retries exceeded with url: /bot528362717:AAGzWK5d0NEkICKK06izaiOoN80jNsqJYrg/getUpdates (Caused by ConnectTimeoutError(<telegram.vendor.ptb_urllib3.urllib3.connection.VerifiedHTTPSConnection object at 0x000000000341F9B0>, 'Connection to api.telegram.org timed out. (connect timeout=5.0)'))
telegram.vendor.ptb_urllib3.urllib3.connectionpool - WARNING - Retrying (Retry(total=2, connect=None, read=None, redirect=None)) after connection broken by 'ConnectTimeoutError(<telegram.vendor.ptb_urllib3.urllib3.connection.VerifiedHTTPSConnection object at 0x000000000341F198>, 'Connection to api.telegram.org timed out. (connect timeout=5.0)')': /bot528362717:AAGzWK5d0NEkICKK06izaiOoN80jNsqJYrg/getUpdates
telegram.vendor.ptb_urllib3.urllib3.connectionpool - WARNING - Retrying (Retry(total=1, connect=None, read=None, redirect=None)) after connection broken by 'ConnectTimeoutError(<telegram.vendor.ptb_urllib3.urllib3.connection.VerifiedHTTPSConnection object at 0x0000000003525B38>, 'Connection to api.telegram.org timed out. (connect timeout=5.0)')': /bot528362717:AAGzWK5d0NEkICKK06izaiOoN80jNsqJYrg/getUpdates
telegram.vendor.ptb_urllib3.urllib3.connectionpool - WARNING - Retrying (Retry(total=0, connect=None, read=None, redirect=None)) after connection broken by 'ConnectTimeoutError(<telegram.vendor.ptb_urllib3.urllib3.connection.VerifiedHTTPSConnection object at 0x00000000035258D0>, 'Connection to api.telegram.org timed out. (connect timeout=5.0)')': /bot528362717:AAGzWK5d0NEkICKK06izaiOoN80jNsqJYrg/getUpdates
telegram.ext.updater - ERROR - Error while getting Updates: urllib3 HTTPError HTTPSConnectionPool(host='api.telegram.org', port=443): Max retries exceeded with url: /bot528362717:AAGzWK5d0NEkICKK06izaiOoN80jNsqJYrg/getUpdates (Caused by ConnectTimeoutError(<telegram.vendor.ptb_urllib3.urllib3.connection.VerifiedHTTPSConnection object at 0x0000000003525F28>, 'Connection to api.telegram.org timed out. (connect timeout=5.0)'))
telegram.vendor.ptb_urllib3.urllib3.connectionpool - WARNING - Retrying (Retry(total=2, connect=None, read=None, redirect=None)) after connection broken by 'ConnectTimeoutError(<telegram.vendor.ptb_urllib3.urllib3.connection.VerifiedHTTPSConnection object at 0x0000000003525E80>, 'Connection to api.telegram.org timed out. (connect timeout=5.0)')': /bot528362717:AAGzWK5d0NEkICKK06izaiOoN80jNsqJYrg/getUpdates
telegram.vendor.ptb_urllib3.urllib3.connectionpool - WARNING - Retrying (Retry(total=1, connect=None, read=None, redirect=None)) after connection broken by 'ConnectTimeoutError(<telegram.vendor.ptb_urllib3.urllib3.connection.VerifiedHTTPSConnection object at 0x0000000003525550>, 'Connection to api.telegram.org timed out. (connect timeout=5.0)')': /bot528362717:AAGzWK5d0NEkICKK06izaiOoN80jNsqJYrg/getUpdates
telegram.vendor.ptb_urllib3.urllib3.connectionpool - WARNING - Retrying (Retry(total=0, connect=None, read=None, redirect=None)) after connection broken by 'ConnectTimeoutError(<telegram.vendor.ptb_urllib3.urllib3.connection.VerifiedHTTPSConnection object at 0x0000000003525908>, 'Connection to api.telegram.org timed out. (connect timeout=5.0)')': /bot528362717:AAGzWK5d0NEkICKK06izaiOoN80jNsqJYrg/getUpdates
telegram.ext.updater - ERROR - Error while getting Updates: urllib3 HTTPError HTTPSConnectionPool(host='api.telegram.org', port=443): Max retries exceeded with url: /bot528362717:AAGzWK5d0NEkICKK06izaiOoN80jNsqJYrg/getUpdates (Caused by ConnectTimeoutError(<telegram.vendor.ptb_urllib3.urllib3.connection.VerifiedHTTPSConnection object at 0x0000000003525A58>, 'Connection to api.telegram.org timed out. (connect timeout=5.0)'))
telegram.vendor.ptb_urllib3.urllib3.connectionpool - WARNING - Retrying (Retry(total=2, connect=None, read=None, redirect=None)) after connection broken by 'ConnectTimeoutError(<telegram.vendor.ptb_urllib3.urllib3.connection.VerifiedHTTPSConnection object at 0x00000000035253C8>, 'Connection to api.telegram.org timed out. (connect timeout=5.0)')': /bot528362717:AAGzWK5d0NEkICKK06izaiOoN80jNsqJYrg/getUpdates
telegram.vendor.ptb_urllib3.urllib3.connectionpool - WARNING - Retrying (Retry(total=1, connect=None, read=None, redirect=None)) after connection broken by 'ConnectTimeoutError(<telegram.vendor.ptb_urllib3.urllib3.connection.VerifiedHTTPSConnection object at 0x0000000003514BE0>, 'Connection to api.telegram.org timed out. (connect timeout=5.0)')': /bot528362717:AAGzWK5d0NEkICKK06izaiOoN80jNsqJYrg/getUpdates
telegram.vendor.ptb_urllib3.urllib3.connectionpool - WARNING - Retrying (Retry(total=0, connect=None, read=None, redirect=None)) after connection broken by 'ConnectTimeoutError(<telegram.vendor.ptb_urllib3.urllib3.connection.VerifiedHTTPSConnection object at 0x0000000003514A20>, 'Connection to api.telegram.org timed out. (connect timeout=5.0)')': /bot528362717:AAGzWK5d0NEkICKK06izaiOoN80jNsqJYrg/getUpdates
telegram.ext.updater - ERROR - Error while getting Updates: urllib3 HTTPError HTTPSConnectionPool(host='api.telegram.org', port=443): Max retries exceeded with url: /bot528362717:AAGzWK5d0NEkICKK06izaiOoN80jNsqJYrg/getUpdates (Caused by ConnectTimeoutError(<telegram.vendor.ptb_urllib3.urllib3.connection.VerifiedHTTPSConnection object at 0x0000000003514DD8>, 'Connection to api.telegram.org timed out. (connect timeout=5.0)'))
telegram.vendor.ptb_urllib3.urllib3.connectionpool - WARNING - Retrying (Retry(total=2, connect=None, read=None, redirect=None)) after connection broken by 'ConnectTimeoutError(<telegram.vendor.ptb_urllib3.urllib3.connection.VerifiedHTTPSConnection object at 0x0000000003514CC0>, 'Connection to api.telegram.org timed out. (connect timeout=5.0)')': /bot528362717:AAGzWK5d0NEkICKK06izaiOoN80jNsqJYrg/getUpdates
telegram.vendor.ptb_urllib3.urllib3.connectionpool - WARNING - Retrying (Retry(total=1, connect=None, read=None, redirect=None)) after connection broken by 'ConnectTimeoutError(<telegram.vendor.ptb_urllib3.urllib3.connectionpool.HTTPSConnectionPool object at 0x00000000033FCB70>, 'Connect timed out. (connect timeout=5.0)')': /bot528362717:AAGzWK5d0NEkICKK06izaiOoN80jNsqJYrg/getUpdates
telegram.vendor.ptb_urllib3.urllib3.connectionpool - WARNING - Retrying (Retry(total=0, connect=None, read=None, redirect=None)) after connection broken by 'ConnectTimeoutError(<telegram.vendor.ptb_urllib3.urllib3.connection.VerifiedHTTPSConnection object at 0x0000000003514160>, 'Connection to api.telegram.org timed out. (connect timeout=5.0)')': /bot528362717:AAGzWK5d0NEkICKK06izaiOoN80jNsqJYrg/getUpdates
telegram.ext.updater - ERROR - Error while getting Updates: urllib3 HTTPError HTTPSConnectionPool(host='api.telegram.org', port=443): Max retries exceeded with url: /bot528362717:AAGzWK5d0NEkICKK06izaiOoN80jNsqJYrg/getUpdates (Caused by ConnectTimeoutError(<telegram.vendor.ptb_urllib3.urllib3.connectionpool.HTTPSConnectionPool object at 0x00000000033FCB70>, 'Connect timed out. (connect timeout=5.0)'))
telegram.vendor.ptb_urllib3.urllib3.connectionpool - WARNING - Retrying (Retry(total=2, connect=None, read=None, redirect=None)) after connection broken by 'ConnectTimeoutError(<telegram.vendor.ptb_urllib3.urllib3.connection.VerifiedHTTPSConnection object at 0x00000000035149B0>, 'Connection to api.telegram.org timed out. (connect timeout=5.0)')': /bot528362717:AAGzWK5d0NEkICKK06izaiOoN80jNsqJYrg/getUpdates
telegram.vendor.ptb_urllib3.urllib3.connectionpool - WARNING - Retrying (Retry(total=1, connect=None, read=None, redirect=None)) after connection broken by 'ConnectTimeoutError(<telegram.vendor.ptb_urllib3.urllib3.connection.VerifiedHTTPSConnection object at 0x0000000003514EB8>, 'Connection to api.telegram.org timed out. (connect timeout=5.0)')': /bot528362717:AAGzWK5d0NEkICKK06izaiOoN80jNsqJYrg/getUpdates
telegram.vendor.ptb_urllib3.urllib3.connectionpool - WARNING - Retrying (Retry(total=0, connect=None, read=None, redirect=None)) after connection broken by 'ConnectTimeoutError(<telegram.vendor.ptb_urllib3.urllib3.connection.VerifiedHTTPSConnection object at 0x00000000035142E8>, 'Connection to api.telegram.org timed out. (connect timeout=5.0)')': /bot528362717:AAGzWK5d0NEkICKK06izaiOoN80jNsqJYrg/getUpdates
telegram.ext.updater - ERROR - Error while getting Updates: urllib3 HTTPError HTTPSConnectionPool(host='api.telegram.org', port=443): Max retries exceeded with url: /bot528362717:AAGzWK5d0NEkICKK06izaiOoN80jNsqJYrg/getUpdates (Caused by ConnectTimeoutError(<telegram.vendor.ptb_urllib3.urllib3.connection.VerifiedHTTPSConnection object at 0x000000000341FF28>, 'Connection to api.telegram.org timed out. (connect timeout=5.0)'))
telegram.vendor.ptb_urllib3.urllib3.connectionpool - WARNING - Retrying (Retry(total=2, connect=None, read=None, redirect=None)) after connection broken by 'ConnectTimeoutError(<telegram.vendor.ptb_urllib3.urllib3.connection.VerifiedHTTPSConnection object at 0x00000000035144A8>, 'Connection to api.telegram.org timed out. (connect timeout=5.0)')': /bot528362717:AAGzWK5d0NEkICKK06izaiOoN80jNsqJYrg/getUpdates
telegram.vendor.ptb_urllib3.urllib3.connectionpool - WARNING - Retrying (Retry(total=1, connect=None, read=None, redirect=None)) after connection broken by 'ConnectTimeoutError(<telegram.vendor.ptb_urllib3.urllib3.connection.VerifiedHTTPSConnection object at 0x000000000341F400>, 'Connection to api.telegram.org timed out. (connect timeout=5.0)')': /bot528362717:AAGzWK5d0NEkICKK06izaiOoN80jNsqJYrg/getUpdates
telegram.vendor.ptb_urllib3.urllib3.connectionpool - WARNING - Retrying (Retry(total=0, connect=None, read=None, redirect=None)) after connection broken by 'ConnectTimeoutError(<telegram.vendor.ptb_urllib3.urllib3.connection.VerifiedHTTPSConnection object at 0x000000000341F4E0>, 'Connection to api.telegram.org timed out. (connect timeout=5.0)')': /bot528362717:AAGzWK5d0NEkICKK06izaiOoN80jNsqJYrg/getUpdates
telegram.ext.updater - ERROR - Error while getting Updates: urllib3 HTTPError HTTPSConnectionPool(host='api.telegram.org', port=443): Max retries exceeded with url: /bot528362717:AAGzWK5d0NEkICKK06izaiOoN80jNsqJYrg/getUpdates (Caused by ConnectTimeoutError(<telegram.vendor.ptb_urllib3.urllib3.connection.VerifiedHTTPSConnection object at 0x000000000341F588>, 'Connection to api.telegram.org timed out. (connect timeout=5.0)'))
telegram.vendor.ptb_urllib3.urllib3.connectionpool - WARNING - Retrying (Retry(total=2, connect=None, read=None, redirect=None)) after connection broken by 'ConnectTimeoutError(<telegram.vendor.ptb_urllib3.urllib3.connection.VerifiedHTTPSConnection object at 0x000000000341F630>, 'Connection to api.telegram.org timed out. (connect timeout=5.0)')': /bot528362717:AAGzWK5d0NEkICKK06izaiOoN80jNsqJYrg/getUpdates
telegram.vendor.ptb_urllib3.urllib3.connectionpool - WARNING - Retrying (Retry(total=1, connect=None, read=None, redirect=None)) after connection broken by 'ConnectTimeoutError(<telegram.vendor.ptb_urllib3.urllib3.connection.VerifiedHTTPSConnection object at 0x000000000341F908>, 'Connection to api.telegram.org timed out. (connect timeout=5.0)')': /bot528362717:AAGzWK5d0NEkICKK06izaiOoN80jNsqJYrg/getUpdates
telegram.vendor.ptb_urllib3.urllib3.connectionpool - WARNING - Retrying (Retry(total=0, connect=None, read=None, redirect=None)) after connection broken by 'ConnectTimeoutError(<telegram.vendor.ptb_urllib3.urllib3.connection.VerifiedHTTPSConnection object at 0x000000000341F470>, 'Connection to api.telegram.org timed out. (connect timeout=5.0)')': /bot528362717:AAGzWK5d0NEkICKK06izaiOoN80jNsqJYrg/getUpdates
telegram.ext.updater - ERROR - Error while getting Updates: urllib3 HTTPError HTTPSConnectionPool(host='api.telegram.org', port=443): Max retries exceeded with url: /bot528362717:AAGzWK5d0NEkICKK06izaiOoN80jNsqJYrg/getUpdates (Caused by ConnectTimeoutError(<telegram.vendor.ptb_urllib3.urllib3.connection.VerifiedHTTPSConnection object at 0x0000000003514978>, 'Connection to api.telegram.org timed out. (connect timeout=5.0)'))
telegram.vendor.ptb_urllib3.urllib3.connectionpool - WARNING - Retrying (Retry(total=2, connect=None, read=None, redirect=None)) after connection broken by 'ConnectTimeoutError(<telegram.vendor.ptb_urllib3.urllib3.connection.VerifiedHTTPSConnection object at 0x00000000035149B0>, 'Connection to api.telegram.org timed out. (connect timeout=5.0)')': /bot528362717:AAGzWK5d0NEkICKK06izaiOoN80jNsqJYrg/getUpdates
telegram.vendor.ptb_urllib3.urllib3.connectionpool - WARNING - Retrying (Retry(total=1, connect=None, read=None, redirect=None)) after connection broken by 'ConnectTimeoutError(<telegram.vendor.ptb_urllib3.urllib3.connection.VerifiedHTTPSConnection object at 0x0000000003514160>, 'Connection to api.telegram.org timed out. (connect timeout=5.0)')': /bot528362717:AAGzWK5d0NEkICKK06izaiOoN80jNsqJYrg/getUpdates
telegram.vendor.ptb_urllib3.urllib3.connectionpool - WARNING - Retrying (Retry(total=0, connect=None, read=None, redirect=None)) after connection broken by 'ConnectTimeoutError(<telegram.vendor.ptb_urllib3.urllib3.connection.VerifiedHTTPSConnection object at 0x00000000035148D0>, 'Connection to api.telegram.org timed out. (connect timeout=5.0)')': /bot528362717:AAGzWK5d0NEkICKK06izaiOoN80jNsqJYrg/getUpdates
telegram.ext.updater - ERROR - Error while getting Updates: urllib3 HTTPError HTTPSConnectionPool(host='api.telegram.org', port=443): Max retries exceeded with url: /bot528362717:AAGzWK5d0NEkICKK06izaiOoN80jNsqJYrg/getUpdates (Caused by ConnectTimeoutError(<telegram.vendor.ptb_urllib3.urllib3.connection.VerifiedHTTPSConnection object at 0x0000000003514278>, 'Connection to api.telegram.org timed out. (connect timeout=5.0)'))
telegram.vendor.ptb_urllib3.urllib3.connectionpool - WARNING - Retrying (Retry(total=2, connect=None, read=None, redirect=None)) after connection broken by 'ConnectTimeoutError(<telegram.vendor.ptb_urllib3.urllib3.connection.VerifiedHTTPSConnection object at 0x0000000003514940>, 'Connection to api.telegram.org timed out. (connect timeout=5.0)')': /bot528362717:AAGzWK5d0NEkICKK06izaiOoN80jNsqJYrg/getUpdates
telegram.vendor.ptb_urllib3.urllib3.connectionpool - WARNING - Retrying (Retry(total=1, connect=None, read=None, redirect=None)) after connection broken by 'ConnectTimeoutError(<telegram.vendor.ptb_urllib3.urllib3.connection.VerifiedHTTPSConnection object at 0x0000000003514A20>, 'Connection to api.telegram.org timed out. (connect timeout=5.0)')': /bot528362717:AAGzWK5d0NEkICKK06izaiOoN80jNsqJYrg/getUpdates
telegram.vendor.ptb_urllib3.urllib3.connectionpool - WARNING - Retrying (Retry(total=0, connect=None, read=None, redirect=None)) after connection broken by 'ConnectTimeoutError(<telegram.vendor.ptb_urllib3.urllib3.connection.VerifiedHTTPSConnection object at 0x0000000003514BE0>, 'Connection to api.telegram.org timed out. (connect timeout=5.0)')': /bot528362717:AAGzWK5d0NEkICKK06izaiOoN80jNsqJYrg/getUpdates
telegram.ext.updater - ERROR - Error while getting Updates: urllib3 HTTPError HTTPSConnectionPool(host='api.telegram.org', port=443): Max retries exceeded with url: /bot528362717:AAGzWK5d0NEkICKK06izaiOoN80jNsqJYrg/getUpdates (Caused by ConnectTimeoutError(<telegram.vendor.ptb_urllib3.urllib3.connection.VerifiedHTTPSConnection object at 0x0000000003514C50>, 'Connection to api.telegram.org timed out. (connect timeout=5.0)'))
telegram.vendor.ptb_urllib3.urllib3.connectionpool - WARNING - Retrying (Retry(total=2, connect=None, read=None, redirect=None)) after connection broken by 'NewConnectionError('<telegram.vendor.ptb_urllib3.urllib3.connection.VerifiedHTTPSConnection object at 0x0000000003514630>: Failed to establish a new connection: [Errno 11004] getaddrinfo failed',)': /bot528362717:AAGzWK5d0NEkICKK06izaiOoN80jNsqJYrg/getUpdates
telegram.vendor.ptb_urllib3.urllib3.connectionpool - WARNING - Retrying (Retry(total=1, connect=None, read=None, redirect=None)) after connection broken by 'NewConnectionError('<telegram.vendor.ptb_urllib3.urllib3.connection.VerifiedHTTPSConnection object at 0x0000000003514B00>: Failed to establish a new connection: [Errno 11004] getaddrinfo failed',)': /bot528362717:AAGzWK5d0NEkICKK06izaiOoN80jNsqJYrg/getUpdates
telegram.vendor.ptb_urllib3.urllib3.connectionpool - WARNING - Retrying (Retry(total=0, connect=None, read=None, redirect=None)) after connection broken by 'NewConnectionError('<telegram.vendor.ptb_urllib3.urllib3.connection.VerifiedHTTPSConnection object at 0x0000000003514F28>: Failed to establish a new connection: [Errno 11004] getaddrinfo failed',)': /bot528362717:AAGzWK5d0NEkICKK06izaiOoN80jNsqJYrg/getUpdates
telegram.ext.updater - ERROR - Error while getting Updates: urllib3 HTTPError HTTPSConnectionPool(host='api.telegram.org', port=443): Max retries exceeded with url: /bot528362717:AAGzWK5d0NEkICKK06izaiOoN80jNsqJYrg/getUpdates (Caused by NewConnectionError('<telegram.vendor.ptb_urllib3.urllib3.connection.VerifiedHTTPSConnection object at 0x00000000033FCC88>: Failed to establish a new connection: [Errno 11004] getaddrinfo failed',))
telegram.vendor.ptb_urllib3.urllib3.connectionpool - WARNING - Retrying (Retry(total=2, connect=None, read=None, redirect=None)) after connection broken by 'ConnectTimeoutError(<telegram.vendor.ptb_urllib3.urllib3.connection.VerifiedHTTPSConnection object at 0x0000000003525A20>, 'Connection to api.telegram.org timed out. (connect timeout=5.0)')': /bot528362717:AAGzWK5d0NEkICKK06izaiOoN80jNsqJYrg/getUpdates
telegram.vendor.ptb_urllib3.urllib3.connectionpool - WARNING - Retrying (Retry(total=1, connect=None, read=None, redirect=None)) after connection broken by 'ConnectTimeoutError(<telegram.vendor.ptb_urllib3.urllib3.connection.VerifiedHTTPSConnection object at 0x0000000003525940>, 'Connection to api.telegram.org timed out. (connect timeout=5.0)')': /bot528362717:AAGzWK5d0NEkICKK06izaiOoN80jNsqJYrg/getUpdates
telegram.vendor.ptb_urllib3.urllib3.connectionpool - WARNING - Retrying (Retry(total=0, connect=None, read=None, redirect=None)) after connection broken by 'ConnectTimeoutError(<telegram.vendor.ptb_urllib3.urllib3.connection.VerifiedHTTPSConnection object at 0x0000000003525F60>, 'Connection to api.telegram.org timed out. (connect timeout=5.0)')': /bot528362717:AAGzWK5d0NEkICKK06izaiOoN80jNsqJYrg/getUpdates
telegram.ext.updater - ERROR - Error while getting Updates: urllib3 HTTPError HTTPSConnectionPool(host='api.telegram.org', port=443): Max retries exceeded with url: /bot528362717:AAGzWK5d0NEkICKK06izaiOoN80jNsqJYrg/getUpdates (Caused by ConnectTimeoutError(<telegram.vendor.ptb_urllib3.urllib3.connection.VerifiedHTTPSConnection object at 0x00000000035259E8>, 'Connection to api.telegram.org timed out. (connect timeout=5.0)'))
telegram.vendor.ptb_urllib3.urllib3.connectionpool - WARNING - Retrying (Retry(total=2, connect=None, read=None, redirect=None)) after connection broken by 'ConnectTimeoutError(<telegram.vendor.ptb_urllib3.urllib3.connection.VerifiedHTTPSConnection object at 0x0000000003525668>, 'Connection to api.telegram.org timed out. (connect timeout=5.0)')': /bot528362717:AAGzWK5d0NEkICKK06izaiOoN80jNsqJYrg/getUpdates
telegram.vendor.ptb_urllib3.urllib3.connectionpool - WARNING - Retrying (Retry(total=1, connect=None, read=None, redirect=None)) after connection broken by 'ConnectTimeoutError(<telegram.vendor.ptb_urllib3.urllib3.connection.VerifiedHTTPSConnection object at 0x0000000003525128>, 'Connection to api.telegram.org timed out. (connect timeout=5.0)')': /bot528362717:AAGzWK5d0NEkICKK06izaiOoN80jNsqJYrg/getUpdates
telegram.vendor.ptb_urllib3.urllib3.connectionpool - WARNING - Retrying (Retry(total=0, connect=None, read=None, redirect=None)) after connection broken by 'ConnectTimeoutError(<telegram.vendor.ptb_urllib3.urllib3.connection.VerifiedHTTPSConnection object at 0x00000000035252E8>, 'Connection to api.telegram.org timed out. (connect timeout=5.0)')': /bot528362717:AAGzWK5d0NEkICKK06izaiOoN80jNsqJYrg/getUpdates
telegram.ext.updater - ERROR - Error while getting Updates: urllib3 HTTPError HTTPSConnectionPool(host='api.telegram.org', port=443): Max retries exceeded with url: /bot528362717:AAGzWK5d0NEkICKK06izaiOoN80jNsqJYrg/getUpdates (Caused by ConnectTimeoutError(<telegram.vendor.ptb_urllib3.urllib3.connection.VerifiedHTTPSConnection object at 0x0000000003525B38>, 'Connection to api.telegram.org timed out. (connect timeout=5.0)'))
telegram.vendor.ptb_urllib3.urllib3.connectionpool - WARNING - Retrying (Retry(total=2, connect=None, read=None, redirect=None)) after connection broken by 'NewConnectionError('<telegram.vendor.ptb_urllib3.urllib3.connection.VerifiedHTTPSConnection object at 0x0000000003525438>: Failed to establish a new connection: [Errno 11004] getaddrinfo failed',)': /bot528362717:AAGzWK5d0NEkICKK06izaiOoN80jNsqJYrg/getUpdates
telegram.vendor.ptb_urllib3.urllib3.connectionpool - WARNING - Retrying (Retry(total=1, connect=None, read=None, redirect=None)) after connection broken by 'NewConnectionError('<telegram.vendor.ptb_urllib3.urllib3.connection.VerifiedHTTPSConnection object at 0x0000000003525CF8>: Failed to establish a new connection: [Errno 11004] getaddrinfo failed',)': /bot528362717:AAGzWK5d0NEkICKK06izaiOoN80jNsqJYrg/getUpdates
telegram.vendor.ptb_urllib3.urllib3.connectionpool - WARNING - Retrying (Retry(total=0, connect=None, read=None, redirect=None)) after connection broken by 'NewConnectionError('<telegram.vendor.ptb_urllib3.urllib3.connection.VerifiedHTTPSConnection object at 0x00000000035255C0>: Failed to establish a new connection: [Errno 11004] getaddrinfo failed',)': /bot528362717:AAGzWK5d0NEkICKK06izaiOoN80jNsqJYrg/getUpdates
telegram.ext.updater - ERROR - Error while getting Updates: urllib3 HTTPError HTTPSConnectionPool(host='api.telegram.org', port=443): Max retries exceeded with url: /bot528362717:AAGzWK5d0NEkICKK06izaiOoN80jNsqJYrg/getUpdates (Caused by NewConnectionError('<telegram.vendor.ptb_urllib3.urllib3.connection.VerifiedHTTPSConnection object at 0x0000000003525C50>: Failed to establish a new connection: [Errno 11004] getaddrinfo failed',))
telegram.vendor.ptb_urllib3.urllib3.connectionpool - WARNING - Retrying (Retry(total=2, connect=None, read=None, redirect=None)) after connection broken by 'NewConnectionError('<telegram.vendor.ptb_urllib3.urllib3.connection.VerifiedHTTPSConnection object at 0x000000000341F550>: Failed to establish a new connection: [Errno 11004] getaddrinfo failed',)': /bot528362717:AAGzWK5d0NEkICKK06izaiOoN80jNsqJYrg/getUpdates
telegram.vendor.ptb_urllib3.urllib3.connectionpool - WARNING - Retrying (Retry(total=1, connect=None, read=None, redirect=None)) after connection broken by 'NewConnectionError('<telegram.vendor.ptb_urllib3.urllib3.connection.VerifiedHTTPSConnection object at 0x000000000341FE10>: Failed to establish a new connection: [Errno 11004] getaddrinfo failed',)': /bot528362717:AAGzWK5d0NEkICKK06izaiOoN80jNsqJYrg/getUpdates
telegram.vendor.ptb_urllib3.urllib3.connectionpool - WARNING - Retrying (Retry(total=0, connect=None, read=None, redirect=None)) after connection broken by 'NewConnectionError('<telegram.vendor.ptb_urllib3.urllib3.connection.VerifiedHTTPSConnection object at 0x000000000341FCF8>: Failed to establish a new connection: [Errno 11004] getaddrinfo failed',)': /bot528362717:AAGzWK5d0NEkICKK06izaiOoN80jNsqJYrg/getUpdates
telegram.ext.updater - ERROR - Error while getting Updates: urllib3 HTTPError HTTPSConnectionPool(host='api.telegram.org', port=443): Max retries exceeded with url: /bot528362717:AAGzWK5d0NEkICKK06izaiOoN80jNsqJYrg/getUpdates (Caused by NewConnectionError('<telegram.vendor.ptb_urllib3.urllib3.connection.VerifiedHTTPSConnection object at 0x0000000003525FD0>: Failed to establish a new connection: [Errno 11004] getaddrinfo failed',))
telegram.vendor.ptb_urllib3.urllib3.connectionpool - WARNING - Retrying (Retry(total=2, connect=None, read=None, redirect=None)) after connection broken by 'NewConnectionError('<telegram.vendor.ptb_urllib3.urllib3.connection.VerifiedHTTPSConnection object at 0x0000000003525D30>: Failed to establish a new connection: [Errno 11004] getaddrinfo failed',)': /bot528362717:AAGzWK5d0NEkICKK06izaiOoN80jNsqJYrg/getUpdates
telegram.vendor.ptb_urllib3.urllib3.connectionpool - WARNING - Retrying (Retry(total=1, connect=None, read=None, redirect=None)) after connection broken by 'NewConnectionError('<telegram.vendor.ptb_urllib3.urllib3.connection.VerifiedHTTPSConnection object at 0x0000000003525390>: Failed to establish a new connection: [Errno 11004] getaddrinfo failed',)': /bot528362717:AAGzWK5d0NEkICKK06izaiOoN80jNsqJYrg/getUpdates
telegram.vendor.ptb_urllib3.urllib3.connectionpool - WARNING - Retrying (Retry(total=0, connect=None, read=None, redirect=None)) after connection broken by 'NewConnectionError('<telegram.vendor.ptb_urllib3.urllib3.connection.VerifiedHTTPSConnection object at 0x0000000003525EB8>: Failed to establish a new connection: [Errno 11004] getaddrinfo failed',)': /bot528362717:AAGzWK5d0NEkICKK06izaiOoN80jNsqJYrg/getUpdates
telegram.ext.updater - ERROR - Error while getting Updates: urllib3 HTTPError HTTPSConnectionPool(host='api.telegram.org', port=443): Max retries exceeded with url: /bot528362717:AAGzWK5d0NEkICKK06izaiOoN80jNsqJYrg/getUpdates (Caused by NewConnectionError('<telegram.vendor.ptb_urllib3.urllib3.connection.VerifiedHTTPSConnection object at 0x0000000003525828>: Failed to establish a new connection: [Errno 11004] getaddrinfo failed',))
telegram.vendor.ptb_urllib3.urllib3.connectionpool - WARNING - Retrying (Retry(total=2, connect=None, read=None, redirect=None)) after connection broken by 'NewConnectionError('<telegram.vendor.ptb_urllib3.urllib3.connection.VerifiedHTTPSConnection object at 0x0000000003525CC0>: Failed to establish a new connection: [Errno 11004] getaddrinfo failed',)': /bot528362717:AAGzWK5d0NEkICKK06izaiOoN80jNsqJYrg/getUpdates
telegram.vendor.ptb_urllib3.urllib3.connectionpool - WARNING - Retrying (Retry(total=1, connect=None, read=None, redirect=None)) after connection broken by 'NewConnectionError('<telegram.vendor.ptb_urllib3.urllib3.connection.VerifiedHTTPSConnection object at 0x0000000003525A58>: Failed to establish a new connection: [Errno 11004] getaddrinfo failed',)': /bot528362717:AAGzWK5d0NEkICKK06izaiOoN80jNsqJYrg/getUpdates
telegram.vendor.ptb_urllib3.urllib3.connectionpool - WARNING - Retrying (Retry(total=0, connect=None, read=None, redirect=None)) after connection broken by 'NewConnectionError('<telegram.vendor.ptb_urllib3.urllib3.connection.VerifiedHTTPSConnection object at 0x00000000033FCA90>: Failed to establish a new connection: [Errno 11004] getaddrinfo failed',)': /bot528362717:AAGzWK5d0NEkICKK06izaiOoN80jNsqJYrg/getUpdates
telegram.ext.updater - ERROR - Error while getting Updates: urllib3 HTTPError HTTPSConnectionPool(host='api.telegram.org', port=443): Max retries exceeded with url: /bot528362717:AAGzWK5d0NEkICKK06izaiOoN80jNsqJYrg/getUpdates (Caused by ConnectTimeoutError(<telegram.vendor.ptb_urllib3.urllib3.connectionpool.HTTPSConnectionPool object at 0x00000000033FCB70>, 'Connect timed out. (connect timeout=5.0)'))
telegram.vendor.ptb_urllib3.urllib3.connectionpool - WARNING - Retrying (Retry(total=2, connect=None, read=None, redirect=None)) after connection broken by 'ConnectTimeoutError(<telegram.vendor.ptb_urllib3.urllib3.connection.VerifiedHTTPSConnection object at 0x0000000003525FD0>, 'Connection to api.telegram.org timed out. (connect timeout=5.0)')': /bot528362717:AAGzWK5d0NEkICKK06izaiOoN80jNsqJYrg/getUpdates
telegram.vendor.ptb_urllib3.urllib3.connectionpool - WARNING - Retrying (Retry(total=1, connect=None, read=None, redirect=None)) after connection broken by 'ConnectTimeoutError(<telegram.vendor.ptb_urllib3.urllib3.connection.VerifiedHTTPSConnection object at 0x0000000003514D68>, 'Connection to api.telegram.org timed out. (connect timeout=5.0)')': /bot528362717:AAGzWK5d0NEkICKK06izaiOoN80jNsqJYrg/getUpdates
telegram.vendor.ptb_urllib3.urllib3.connectionpool - WARNING - Retrying (Retry(total=0, connect=None, read=None, redirect=None)) after connection broken by 'ConnectTimeoutError(<telegram.vendor.ptb_urllib3.urllib3.connection.VerifiedHTTPSConnection object at 0x0000000003514630>, 'Connection to api.telegram.org timed out. (connect timeout=5.0)')': /bot528362717:AAGzWK5d0NEkICKK06izaiOoN80jNsqJYrg/getUpdates
telegram.ext.updater - ERROR - Error while getting Updates: urllib3 HTTPError HTTPSConnectionPool(host='api.telegram.org', port=443): Max retries exceeded with url: /bot528362717:AAGzWK5d0NEkICKK06izaiOoN80jNsqJYrg/getUpdates (Caused by ConnectTimeoutError(<telegram.vendor.ptb_urllib3.urllib3.connection.VerifiedHTTPSConnection object at 0x0000000003514E10>, 'Connection to api.telegram.org timed out. (connect timeout=5.0)'))
telegram.vendor.ptb_urllib3.urllib3.connectionpool - WARNING - Retrying (Retry(total=2, connect=None, read=None, redirect=None)) after connection broken by 'ConnectTimeoutError(<telegram.vendor.ptb_urllib3.urllib3.connection.VerifiedHTTPSConnection object at 0x00000000035144E0>, 'Connection to api.telegram.org timed out. (connect timeout=5.0)')': /bot528362717:AAGzWK5d0NEkICKK06izaiOoN80jNsqJYrg/getUpdates
telegram.vendor.ptb_urllib3.urllib3.connectionpool - WARNING - Retrying (Retry(total=1, connect=None, read=None, redirect=None)) after connection broken by 'ConnectTimeoutError(<telegram.vendor.ptb_urllib3.urllib3.connection.VerifiedHTTPSConnection object at 0x0000000003514E80>, 'Connection to api.telegram.org timed out. (connect timeout=5.0)')': /bot528362717:AAGzWK5d0NEkICKK06izaiOoN80jNsqJYrg/getUpdates
telegram.vendor.ptb_urllib3.urllib3.connectionpool - WARNING - Retrying (Retry(total=0, connect=None, read=None, redirect=None)) after connection broken by 'ConnectTimeoutError(<telegram.vendor.ptb_urllib3.urllib3.connection.VerifiedHTTPSConnection object at 0x0000000003514898>, 'Connection to api.telegram.org timed out. (connect timeout=5.0)')': /bot528362717:AAGzWK5d0NEkICKK06izaiOoN80jNsqJYrg/getUpdates
telegram.ext.updater - ERROR - Error while getting Updates: urllib3 HTTPError HTTPSConnectionPool(host='api.telegram.org', port=443): Max retries exceeded with url: /bot528362717:AAGzWK5d0NEkICKK06izaiOoN80jNsqJYrg/getUpdates (Caused by ConnectTimeoutError(<telegram.vendor.ptb_urllib3.urllib3.connection.VerifiedHTTPSConnection object at 0x0000000003514CF8>, 'Connection to api.telegram.org timed out. (connect timeout=5.0)'))
telegram.vendor.ptb_urllib3.urllib3.connectionpool - WARNING - Retrying (Retry(total=2, connect=None, read=None, redirect=None)) after connection broken by 'ConnectTimeoutError(<telegram.vendor.ptb_urllib3.urllib3.connection.VerifiedHTTPSConnection object at 0x0000000003514B38>, 'Connection to api.telegram.org timed out. (connect timeout=5.0)')': /bot528362717:AAGzWK5d0NEkICKK06izaiOoN80jNsqJYrg/getUpdates
telegram.vendor.ptb_urllib3.urllib3.connectionpool - WARNING - Retrying (Retry(total=1, connect=None, read=None, redirect=None)) after connection broken by 'NewConnectionError('<telegram.vendor.ptb_urllib3.urllib3.connection.VerifiedHTTPSConnection object at 0x0000000003514F60>: Failed to establish a new connection: [Errno 11004] getaddrinfo failed',)': /bot528362717:AAGzWK5d0NEkICKK06izaiOoN80jNsqJYrg/getUpdates
telegram.vendor.ptb_urllib3.urllib3.connectionpool - WARNING - Retrying (Retry(total=0, connect=None, read=None, redirect=None)) after connection broken by 'NewConnectionError('<telegram.vendor.ptb_urllib3.urllib3.connection.VerifiedHTTPSConnection object at 0x0000000003514EF0>: Failed to establish a new connection: [Errno 11004] getaddrinfo failed',)': /bot528362717:AAGzWK5d0NEkICKK06izaiOoN80jNsqJYrg/getUpdates
telegram.ext.updater - ERROR - Error while getting Updates: urllib3 HTTPError HTTPSConnectionPool(host='api.telegram.org', port=443): Max retries exceeded with url: /bot528362717:AAGzWK5d0NEkICKK06izaiOoN80jNsqJYrg/getUpdates (Caused by ConnectTimeoutError(<telegram.vendor.ptb_urllib3.urllib3.connection.VerifiedHTTPSConnection object at 0x0000000003514588>, 'Connection to api.telegram.org timed out. (connect timeout=5.0)'))
telegram.vendor.ptb_urllib3.urllib3.connectionpool - WARNING - Retrying (Retry(total=2, connect=None, read=None, redirect=None)) after connection broken by 'ConnectTimeoutError(<telegram.vendor.ptb_urllib3.urllib3.connection.VerifiedHTTPSConnection object at 0x0000000003514278>, 'Connection to api.telegram.org timed out. (connect timeout=5.0)')': /bot528362717:AAGzWK5d0NEkICKK06izaiOoN80jNsqJYrg/getUpdates
telegram.vendor.ptb_urllib3.urllib3.connectionpool - WARNING - Retrying (Retry(total=1, connect=None, read=None, redirect=None)) after connection broken by 'ConnectTimeoutError(<telegram.vendor.ptb_urllib3.urllib3.connection.VerifiedHTTPSConnection object at 0x000000000341FC50>, 'Connection to api.telegram.org timed out. (connect timeout=5.0)')': /bot528362717:AAGzWK5d0NEkICKK06izaiOoN80jNsqJYrg/getUpdates
telegram.vendor.ptb_urllib3.urllib3.connectionpool - WARNING - Retrying (Retry(total=0, connect=None, read=None, redirect=None)) after connection broken by 'ConnectTimeoutError(<telegram.vendor.ptb_urllib3.urllib3.connection.VerifiedHTTPSConnection object at 0x000000000341F1D0>, 'Connection to api.telegram.org timed out. (connect timeout=5.0)')': /bot528362717:AAGzWK5d0NEkICKK06izaiOoN80jNsqJYrg/getUpdates
telegram.ext.updater - ERROR - Error while getting Updates: urllib3 HTTPError HTTPSConnectionPool(host='api.telegram.org', port=443): Max retries exceeded with url: /bot528362717:AAGzWK5d0NEkICKK06izaiOoN80jNsqJYrg/getUpdates (Caused by ConnectTimeoutError(<telegram.vendor.ptb_urllib3.urllib3.connection.VerifiedHTTPSConnection object at 0x000000000341F6D8>, 'Connection to api.telegram.org timed out. (connect timeout=5.0)'))
telegram.vendor.ptb_urllib3.urllib3.connectionpool - WARNING - Retrying (Retry(total=2, connect=None, read=None, redirect=None)) after connection broken by 'ConnectTimeoutError(<telegram.vendor.ptb_urllib3.urllib3.connection.VerifiedHTTPSConnection object at 0x000000000341F2B0>, 'Connection to api.telegram.org timed out. (connect timeout=5.0)')': /bot528362717:AAGzWK5d0NEkICKK06izaiOoN80jNsqJYrg/getUpdates
telegram.vendor.ptb_urllib3.urllib3.connectionpool - WARNING - Retrying (Retry(total=1, connect=None, read=None, redirect=None)) after connection broken by 'ConnectTimeoutError(<telegram.vendor.ptb_urllib3.urllib3.connection.VerifiedHTTPSConnection object at 0x000000000341FCC0>, 'Connection to api.telegram.org timed out. (connect timeout=5.0)')': /bot528362717:AAGzWK5d0NEkICKK06izaiOoN80jNsqJYrg/getUpdates
telegram.vendor.ptb_urllib3.urllib3.connectionpool - WARNING - Retrying (Retry(total=0, connect=None, read=None, redirect=None)) after connection broken by 'ConnectTimeoutError(<telegram.vendor.ptb_urllib3.urllib3.connection.VerifiedHTTPSConnection object at 0x0000000003438EF0>, 'Connection to api.telegram.org timed out. (connect timeout=5.0)')': /bot528362717:AAGzWK5d0NEkICKK06izaiOoN80jNsqJYrg/getUpdates
telegram.ext.updater - ERROR - Error while getting Updates: urllib3 HTTPError HTTPSConnectionPool(host='api.telegram.org', port=443): Max retries exceeded with url: /bot528362717:AAGzWK5d0NEkICKK06izaiOoN80jNsqJYrg/getUpdates (Caused by ConnectTimeoutError(<telegram.vendor.ptb_urllib3.urllib3.connection.VerifiedHTTPSConnection object at 0x0000000003438F98>, 'Connection to api.telegram.org timed out. (connect timeout=5.0)'))
telegram.vendor.ptb_urllib3.urllib3.connectionpool - WARNING - Retrying (Retry(total=2, connect=None, read=None, redirect=None)) after connection broken by 'ConnectTimeoutError(<telegram.vendor.ptb_urllib3.urllib3.connection.VerifiedHTTPSConnection object at 0x00000000035149B0>, 'Connection to api.telegram.org timed out. (connect timeout=5.0)')': /bot528362717:AAGzWK5d0NEkICKK06izaiOoN80jNsqJYrg/getUpdates
telegram.vendor.ptb_urllib3.urllib3.connectionpool - WARNING - Retrying (Retry(total=1, connect=None, read=None, redirect=None)) after connection broken by 'ConnectTimeoutError(<telegram.vendor.ptb_urllib3.urllib3.connection.VerifiedHTTPSConnection object at 0x0000000003514F60>, 'Connection to api.telegram.org timed out. (connect timeout=5.0)')': /bot528362717:AAGzWK5d0NEkICKK06izaiOoN80jNsqJYrg/getUpdates
telegram.vendor.ptb_urllib3.urllib3.connectionpool - WARNING - Retrying (Retry(total=0, connect=None, read=None, redirect=None)) after connection broken by 'ConnectTimeoutError(<telegram.vendor.ptb_urllib3.urllib3.connection.VerifiedHTTPSConnection object at 0x00000000035140F0>, 'Connection to api.telegram.org timed out. (connect timeout=5.0)')': /bot528362717:AAGzWK5d0NEkICKK06izaiOoN80jNsqJYrg/getUpdates
telegram.ext.updater - ERROR - Error while getting Updates: urllib3 HTTPError HTTPSConnectionPool(host='api.telegram.org', port=443): Max retries exceeded with url: /bot528362717:AAGzWK5d0NEkICKK06izaiOoN80jNsqJYrg/getUpdates (Caused by ConnectTimeoutError(<telegram.vendor.ptb_urllib3.urllib3.connection.VerifiedHTTPSConnection object at 0x0000000003514710>, 'Connection to api.telegram.org timed out. (connect timeout=5.0)'))
telegram.vendor.ptb_urllib3.urllib3.connectionpool - WARNING - Retrying (Retry(total=2, connect=None, read=None, redirect=None)) after connection broken by 'ConnectTimeoutError(<telegram.vendor.ptb_urllib3.urllib3.connection.VerifiedHTTPSConnection object at 0x0000000003514BE0>, 'Connection to api.telegram.org timed out. (connect timeout=5.0)')': /bot528362717:AAGzWK5d0NEkICKK06izaiOoN80jNsqJYrg/getUpdates
telegram.vendor.ptb_urllib3.urllib3.connectionpool - WARNING - Retrying (Retry(total=1, connect=None, read=None, redirect=None)) after connection broken by 'ConnectTimeoutError(<telegram.vendor.ptb_urllib3.urllib3.connection.VerifiedHTTPSConnection object at 0x0000000003514320>, 'Connection to api.telegram.org timed out. (connect timeout=5.0)')': /bot528362717:AAGzWK5d0NEkICKK06izaiOoN80jNsqJYrg/getUpdates
telegram.vendor.ptb_urllib3.urllib3.connectionpool - WARNING - Retrying (Retry(total=0, connect=None, read=None, redirect=None)) after connection broken by 'ConnectTimeoutError(<telegram.vendor.ptb_urllib3.urllib3.connection.VerifiedHTTPSConnection object at 0x0000000003514FD0>, 'Connection to api.telegram.org timed out. (connect timeout=5.0)')': /bot528362717:AAGzWK5d0NEkICKK06izaiOoN80jNsqJYrg/getUpdates
telegram.ext.updater - ERROR - Error while getting Updates: urllib3 HTTPError HTTPSConnectionPool(host='api.telegram.org', port=443): Max retries exceeded with url: /bot528362717:AAGzWK5d0NEkICKK06izaiOoN80jNsqJYrg/getUpdates (Caused by ConnectTimeoutError(<telegram.vendor.ptb_urllib3.urllib3.connection.VerifiedHTTPSConnection object at 0x0000000003514E10>, 'Connection to api.telegram.org timed out. (connect timeout=5.0)'))
telegram.vendor.ptb_urllib3.urllib3.connectionpool - WARNING - Retrying (Retry(total=2, connect=None, read=None, redirect=None)) after connection broken by 'ConnectTimeoutError(<telegram.vendor.ptb_urllib3.urllib3.connection.VerifiedHTTPSConnection object at 0x0000000003514940>, 'Connection to api.telegram.org timed out. (connect timeout=5.0)')': /bot528362717:AAGzWK5d0NEkICKK06izaiOoN80jNsqJYrg/getUpdates
telegram.vendor.ptb_urllib3.urllib3.connectionpool - WARNING - Retrying (Retry(total=1, connect=None, read=None, redirect=None)) after connection broken by 'ConnectTimeoutError(<telegram.vendor.ptb_urllib3.urllib3.connection.VerifiedHTTPSConnection object at 0x0000000003514390>, 'Connection to api.telegram.org timed out. (connect timeout=5.0)')': /bot528362717:AAGzWK5d0NEkICKK06izaiOoN80jNsqJYrg/getUpdates
telegram.vendor.ptb_urllib3.urllib3.connectionpool - WARNING - Retrying (Retry(total=0, connect=None, read=None, redirect=None)) after connection broken by 'ConnectTimeoutError(<telegram.vendor.ptb_urllib3.urllib3.connection.VerifiedHTTPSConnection object at 0x0000000003514CC0>, 'Connection to api.telegram.org timed out. (connect timeout=5.0)')': /bot528362717:AAGzWK5d0NEkICKK06izaiOoN80jNsqJYrg/getUpdates
telegram.ext.updater - ERROR - Error while getting Updates: urllib3 HTTPError HTTPSConnectionPool(host='api.telegram.org', port=443): Max retries exceeded with url: /bot528362717:AAGzWK5d0NEkICKK06izaiOoN80jNsqJYrg/getUpdates (Caused by ConnectTimeoutError(<telegram.vendor.ptb_urllib3.urllib3.connection.VerifiedHTTPSConnection object at 0x00000000033FCC88>, 'Connection to api.telegram.org timed out. (connect timeout=5.0)'))
telegram.vendor.ptb_urllib3.urllib3.connectionpool - WARNING - Retrying (Retry(total=2, connect=None, read=None, redirect=None)) after connection broken by 'ConnectTimeoutError(<telegram.vendor.ptb_urllib3.urllib3.connection.VerifiedHTTPSConnection object at 0x0000000003525048>, 'Connection to api.telegram.org timed out. (connect timeout=5.0)')': /bot528362717:AAGzWK5d0NEkICKK06izaiOoN80jNsqJYrg/getUpdates
telegram.vendor.ptb_urllib3.urllib3.connectionpool - WARNING - Retrying (Retry(total=1, connect=None, read=None, redirect=None)) after connection broken by 'ConnectTimeoutError(<telegram.vendor.ptb_urllib3.urllib3.connection.VerifiedHTTPSConnection object at 0x0000000003525CC0>, 'Connection to api.telegram.org timed out. (connect timeout=5.0)')': /bot528362717:AAGzWK5d0NEkICKK06izaiOoN80jNsqJYrg/getUpdates
telegram.vendor.ptb_urllib3.urllib3.connectionpool - WARNING - Retrying (Retry(total=0, connect=None, read=None, redirect=None)) after connection broken by 'ConnectTimeoutError(<telegram.vendor.ptb_urllib3.urllib3.connection.VerifiedHTTPSConnection object at 0x0000000003525668>, 'Connection to api.telegram.org timed out. (connect timeout=5.0)')': /bot528362717:AAGzWK5d0NEkICKK06izaiOoN80jNsqJYrg/getUpdates
telegram.ext.updater - ERROR - Error while getting Updates: urllib3 HTTPError HTTPSConnectionPool(host='api.telegram.org', port=443): Max retries exceeded with url: /bot528362717:AAGzWK5d0NEkICKK06izaiOoN80jNsqJYrg/getUpdates (Caused by ConnectTimeoutError(<telegram.vendor.ptb_urllib3.urllib3.connection.VerifiedHTTPSConnection object at 0x0000000003525358>, 'Connection to api.telegram.org timed out. (connect timeout=5.0)'))
telegram.vendor.ptb_urllib3.urllib3.connectionpool - WARNING - Retrying (Retry(total=2, connect=None, read=None, redirect=None)) after connection broken by 'ConnectTimeoutError(<telegram.vendor.ptb_urllib3.urllib3.connection.VerifiedHTTPSConnection object at 0x0000000003525828>, 'Connection to api.telegram.org timed out. (connect timeout=5.0)')': /bot528362717:AAGzWK5d0NEkICKK06izaiOoN80jNsqJYrg/getUpdates
telegram.vendor.ptb_urllib3.urllib3.connectionpool - WARNING - Retrying (Retry(total=1, connect=None, read=None, redirect=None)) after connection broken by 'ConnectTimeoutError(<telegram.vendor.ptb_urllib3.urllib3.connection.VerifiedHTTPSConnection object at 0x0000000003525C18>, 'Connection to api.telegram.org timed out. (connect timeout=5.0)')': /bot528362717:AAGzWK5d0NEkICKK06izaiOoN80jNsqJYrg/getUpdates
telegram.vendor.ptb_urllib3.urllib3.connectionpool - WARNING - Retrying (Retry(total=0, connect=None, read=None, redirect=None)) after connection broken by 'ConnectTimeoutError(<telegram.vendor.ptb_urllib3.urllib3.connection.VerifiedHTTPSConnection object at 0x0000000003438E48>, 'Connection to api.telegram.org timed out. (connect timeout=5.0)')': /bot528362717:AAGzWK5d0NEkICKK06izaiOoN80jNsqJYrg/getUpdates
telegram.ext.updater - ERROR - Error while getting Updates: urllib3 HTTPError HTTPSConnectionPool(host='api.telegram.org', port=443): Max retries exceeded with url: /bot528362717:AAGzWK5d0NEkICKK06izaiOoN80jNsqJYrg/getUpdates (Caused by ConnectTimeoutError(<telegram.vendor.ptb_urllib3.urllib3.connection.VerifiedHTTPSConnection object at 0x0000000003438DA0>, 'Connection to api.telegram.org timed out. (connect timeout=5.0)'))
telegram.vendor.ptb_urllib3.urllib3.connectionpool - WARNING - Retrying (Retry(total=2, connect=None, read=None, redirect=None)) after connection broken by 'ConnectTimeoutError(<telegram.vendor.ptb_urllib3.urllib3.connection.VerifiedHTTPSConnection object at 0x000000000340EEB8>, 'Connection to api.telegram.org timed out. (connect timeout=5.0)')': /bot528362717:AAGzWK5d0NEkICKK06izaiOoN80jNsqJYrg/getUpdates
telegram.vendor.ptb_urllib3.urllib3.connectionpool - WARNING - Retrying (Retry(total=1, connect=None, read=None, redirect=None)) after connection broken by 'ConnectTimeoutError(<telegram.vendor.ptb_urllib3.urllib3.connection.VerifiedHTTPSConnection object at 0x000000000340EE10>, 'Connection to api.telegram.org timed out. (connect timeout=5.0)')': /bot528362717:AAGzWK5d0NEkICKK06izaiOoN80jNsqJYrg/getUpdates
telegram.vendor.ptb_urllib3.urllib3.connectionpool - WARNING - Retrying (Retry(total=0, connect=None, read=None, redirect=None)) after connection broken by 'ConnectTimeoutError(<telegram.vendor.ptb_urllib3.urllib3.connection.VerifiedHTTPSConnection object at 0x000000000340E048>, 'Connection to api.telegram.org timed out. (connect timeout=5.0)')': /bot528362717:AAGzWK5d0NEkICKK06izaiOoN80jNsqJYrg/getUpdates
telegram.ext.updater - ERROR - Error while getting Updates: urllib3 HTTPError HTTPSConnectionPool(host='api.telegram.org', port=443): Max retries exceeded with url: /bot528362717:AAGzWK5d0NEkICKK06izaiOoN80jNsqJYrg/getUpdates (Caused by ConnectTimeoutError(<telegram.vendor.ptb_urllib3.urllib3.connection.VerifiedHTTPSConnection object at 0x000000000340E748>, 'Connection to api.telegram.org timed out. (connect timeout=5.0)'))
telegram.vendor.ptb_urllib3.urllib3.connectionpool - WARNING - Retrying (Retry(total=2, connect=None, read=None, redirect=None)) after connection broken by 'ConnectTimeoutError(<telegram.vendor.ptb_urllib3.urllib3.connection.VerifiedHTTPSConnection object at 0x000000000340E710>, 'Connection to api.telegram.org timed out. (connect timeout=5.0)')': /bot528362717:AAGzWK5d0NEkICKK06izaiOoN80jNsqJYrg/getUpdates
telegram.vendor.ptb_urllib3.urllib3.connectionpool - WARNING - Retrying (Retry(total=1, connect=None, read=None, redirect=None)) after connection broken by 'ConnectTimeoutError(<telegram.vendor.ptb_urllib3.urllib3.connection.VerifiedHTTPSConnection object at 0x000000000340E9E8>, 'Connection to api.telegram.org timed out. (connect timeout=5.0)')': /bot528362717:AAGzWK5d0NEkICKK06izaiOoN80jNsqJYrg/getUpdates
telegram.vendor.ptb_urllib3.urllib3.connectionpool - WARNING - Retrying (Retry(total=0, connect=None, read=None, redirect=None)) after connection broken by 'ConnectTimeoutError(<telegram.vendor.ptb_urllib3.urllib3.connection.VerifiedHTTPSConnection object at 0x0000000003525FD0>, 'Connection to api.telegram.org timed out. (connect timeout=5.0)')': /bot528362717:AAGzWK5d0NEkICKK06izaiOoN80jNsqJYrg/getUpdates
telegram.ext.updater - ERROR - Error while getting Updates: urllib3 HTTPError HTTPSConnectionPool(host='api.telegram.org', port=443): Max retries exceeded with url: /bot528362717:AAGzWK5d0NEkICKK06izaiOoN80jNsqJYrg/getUpdates (Caused by ConnectTimeoutError(<telegram.vendor.ptb_urllib3.urllib3.connection.VerifiedHTTPSConnection object at 0x0000000003525C50>, 'Connection to api.telegram.org timed out. (connect timeout=5.0)'))
telegram.vendor.ptb_urllib3.urllib3.connectionpool - WARNING - Retrying (Retry(total=2, connect=None, read=None, redirect=None)) after connection broken by 'NewConnectionError('<telegram.vendor.ptb_urllib3.urllib3.connection.VerifiedHTTPSConnection object at 0x0000000003525278>: Failed to establish a new connection: [Errno 11004] getaddrinfo failed',)': /bot528362717:AAGzWK5d0NEkICKK06izaiOoN80jNsqJYrg/getUpdates
telegram.vendor.ptb_urllib3.urllib3.connectionpool - WARNING - Retrying (Retry(total=1, connect=None, read=None, redirect=None)) after connection broken by 'NewConnectionError('<telegram.vendor.ptb_urllib3.urllib3.connection.VerifiedHTTPSConnection object at 0x00000000035259E8>: Failed to establish a new connection: [Errno 11004] getaddrinfo failed',)': /bot528362717:AAGzWK5d0NEkICKK06izaiOoN80jNsqJYrg/getUpdates
telegram.vendor.ptb_urllib3.urllib3.connectionpool - WARNING - Retrying (Retry(total=0, connect=None, read=None, redirect=None)) after connection broken by 'NewConnectionError('<telegram.vendor.ptb_urllib3.urllib3.connection.VerifiedHTTPSConnection object at 0x0000000003525128>: Failed to establish a new connection: [Errno 11004] getaddrinfo failed',)': /bot528362717:AAGzWK5d0NEkICKK06izaiOoN80jNsqJYrg/getUpdates
telegram.ext.updater - ERROR - Error while getting Updates: urllib3 HTTPError HTTPSConnectionPool(host='api.telegram.org', port=443): Max retries exceeded with url: /bot528362717:AAGzWK5d0NEkICKK06izaiOoN80jNsqJYrg/getUpdates (Caused by NewConnectionError('<telegram.vendor.ptb_urllib3.urllib3.connection.VerifiedHTTPSConnection object at 0x0000000003525A90>: Failed to establish a new connection: [Errno 11004] getaddrinfo failed',))
telegram.vendor.ptb_urllib3.urllib3.connectionpool - WARNING - Retrying (Retry(total=2, connect=None, read=None, redirect=None)) after connection broken by 'NewConnectionError('<telegram.vendor.ptb_urllib3.urllib3.connection.VerifiedHTTPSConnection object at 0x0000000003525550>: Failed to establish a new connection: [Errno 11004] getaddrinfo failed',)': /bot528362717:AAGzWK5d0NEkICKK06izaiOoN80jNsqJYrg/getUpdates
telegram.vendor.ptb_urllib3.urllib3.connectionpool - WARNING - Retrying (Retry(total=1, connect=None, read=None, redirect=None)) after connection broken by 'NewConnectionError('<telegram.vendor.ptb_urllib3.urllib3.connection.VerifiedHTTPSConnection object at 0x00000000033FCAC8>: Failed to establish a new connection: [Errno 11004] getaddrinfo failed',)': /bot528362717:AAGzWK5d0NEkICKK06izaiOoN80jNsqJYrg/getUpdates
telegram.vendor.ptb_urllib3.urllib3.connectionpool - WARNING - Retrying (Retry(total=0, connect=None, read=None, redirect=None)) after connection broken by 'NewConnectionError('<telegram.vendor.ptb_urllib3.urllib3.connection.VerifiedHTTPSConnection object at 0x0000000003514630>: Failed to establish a new connection: [Errno 11004] getaddrinfo failed',)': /bot528362717:AAGzWK5d0NEkICKK06izaiOoN80jNsqJYrg/getUpdates
telegram.ext.updater - ERROR - Error while getting Updates: urllib3 HTTPError HTTPSConnectionPool(host='api.telegram.org', port=443): Max retries exceeded with url: /bot528362717:AAGzWK5d0NEkICKK06izaiOoN80jNsqJYrg/getUpdates (Caused by NewConnectionError('<telegram.vendor.ptb_urllib3.urllib3.connection.VerifiedHTTPSConnection object at 0x00000000035141D0>: Failed to establish a new connection: [Errno 11004] getaddrinfo failed',))
telegram.ext.updater - ERROR - Error while getting Updates: Timed out
telegram.ext.updater - WARNING - Exiting immediately!
telegram.ext.updater - ERROR - Error while getting Updates: Timed out
telegram.ext.updater - ERROR - Error while getting Updates: Timed out
telegram.ext.updater - ERROR - Error while getting Updates: Timed out
telegram.ext.updater - ERROR - Error while getting Updates: Timed out
telegram.ext.updater - WARNING - Exiting immediately!
telegram.ext.updater - WARNING - Exiting immediately!
telegram.ext.updater - WARNING - Exiting immediately!
telegram.ext.updater - WARNING - Exiting immediately!
telegram.ext.updater - WARNING - Exiting immediately!
telegram.ext.dispatcher - ERROR - An uncaught error was raised while processing the update
Traceback (most recent call last):
  File "C:\Python34\lib\site-packages\telegram\ext\dispatcher.py", line 279, in process_update
    handler.handle_update(update, self)
  File "C:\Python34\lib\site-packages\telegram\ext\commandhandler.py", line 171, in handle_update
    return self.callback(dispatcher.bot, update, **optional_args)
  File "my_bot.py", line 31, in define_constellation
    update.message.reply_text(planet_name+cons)
TypeError: Can't convert 'tuple' object to str implicitly
telegram.ext.updater - WARNING - Exiting immediately!
telegram.ext.dispatcher - ERROR - An uncaught error was raised while processing the update
Traceback (most recent call last):
  File "C:\Python34\lib\site-packages\telegram\ext\dispatcher.py", line 279, in process_update
    handler.handle_update(update, self)
  File "C:\Python34\lib\site-packages\telegram\ext\commandhandler.py", line 171, in handle_update
    return self.callback(dispatcher.bot, update, **optional_args)
  File "my_bot.py", line 29, in define_constellation
    planet_object = getattr(ephem, planet_name)
AttributeError: 'module' object has no attribute 'mars'
telegram.ext.updater - WARNING - Exiting immediately!
telegram.ext.updater - ERROR - Error while getting Updates: Timed out
telegram.ext.updater - WARNING - Exiting immediately!
